Workbook

Sheet Series 100 Design
A1: SERIES 100: PRELIMINARIES
A3: Item | B3: Description | C3: Qty | D3: Unit
E4: Tayside Contracts | G4: John McGeady Ltd | I4: Lightways (Contractors) Ltd | K4: Newlay Civil Engineering | M4: T & N Gilmartin (Contractors) Ltd | O4: Tarmac Limited
B6: Temporary Accommodation | E6: Rate | F6: Cost | G6: Rate | H6: Cost | I6: Rate | J6: Cost | K6: Rate | L6: Cost | M6: Rate | N6: Cost | O6: Rate | P6: Cost
A8: 1/001 | B8: Erection of offices and messes for the Contractor (Comply with appendix 0/6) | C8: ='Series 100 Input'!C8 -> 1 | D8: Item | E8: 120 | F8: =C8*E8 -> 120 | G8: 100 | H8: =C8*G8 -> 100 | I8: 0.01 | J8: =C8*I8 -> 0.01 | K8: 200 | L8: =C8*K8 -> 200 | M8: 500 | N8: =C8*M8 -> 500 | O8: 500 | P8: =C8*O8 -> 500
A10: 1/002 | B10: Servicing of offices and messes for the Contractor (Comply with appendix 0/6) | C10: ='Series 100 Input'!C10 -> 10 | D10: Day | E10: 100 | F10: =C10*E10 -> 1000 | G10: 20 | H10: =C10*G10 -> 200 | I10: 41.9 | J10: =C10*I10 -> 419 | K10: 50 | L10: =C10*K10 -> 500 | M10: 250 | N10: =C10*M10 -> 2500 | O10: 100 | P10: =C10*O10 -> 1000
A12: 1/003 | B12: Dismantling of offices and messes for the Contractor (Comply with appendix 0/6) | C12: ='Series 100 Input'!C12 -> 1 | D12: Item | E12: 120 | F12: =C12*E12 -> 120 | G12: 100 | H12: =C12*G12 -> 100 | I12: 0.01 | J12: =C12*I12 -> 0.01 | K12: 100 | L12: =C12*K12 -> 100 | M12: 500 | N12: =C12*M12 -> 500 | O12: 500 | P12: =C12*O12 -> 500
A14: 1/004 | B14: Erection of stores and workshops for the Contractor | C14: ='Series 100 Input'!C14 -> 0 | D14: Item | E14: 120 | F14: =C14*E14 -> 0 | G14: 100 | H14: =C14*G14 -> 0 | I14: 287.63 | J14: =C14*I14 -> 0 | K14: 0 | L14: =C14*K14 -> 0 | M14: 500 | N14: =C14*M14 -> 0 | O14: 150 | P14: =C14*O14 -> 0
A16: 1/005 | B16: Servicing of stores and workshops for the Contractor | C16: ='Series 100 Input'!C16 -> 0 | D16: Day | E16: 100 | F16: =C16*E16 -> 0 | G16: 10 | H16: =C16*G16 -> 0 | I16: 0.01 | J16: =C16*I16 -> 0 | K16: 0 | L16: =C16*K16 -> 0 | M16: 50 | N16: =C16*M16 -> 0 | O16: 25 | P16: =C16*O16 -> 0
A18: 1/006 | B18: Dismantling of stores and workshops for the Contractor | C18: ='Series 100 Input'!C18 -> 0 | D18: Item | E18: 120 | F18: =C18*E18 -> 0 | G18: 100 | H18: =C18*G18 -> 0 | I18: 287.63 | J18: =C18*I18 -> 0 | K18: 0 | L18: =C18*K18 -> 0 | M18: 500 | N18: =C18*M18 -> 0 | O18: 150 | P18: =C18*O18 -> 0
B20: Information Boards & Signs
A22: 1/007 | B22: Uplift, place out, maintain and remove Information board as per example on P.23 of the Safety at Street Works and Road Works | C22: ='Series 100 Input'!C22 -> 0 | D22: No | E22: 217.8 | F22: =C22*E22 -> 0 | G22: 10 | H22: =C22*G22 -> 0 | I22: 6.95 | J22: =C22*I22 -> 0 | K22: 25 | L22: =C22*K22 -> 0 | M22: 55 | N22: =C22*M22 -> 0 | O22: 57.5 | P22: =C22*O22 -> 0
A24: 1/008 | B24: Supply, place out, maintain and remove Information sign as described | C24: ='Series 100 Input'!C24 -> 0 | D24: No | E24: 217.8 | F24: =C24*E24 -> 0 | G24: 10 | H24: =C24*G24 -> 0 | I24: 18.45 | J24: =C24*I24 -> 0 | K24: 75 | L24: =C24*K24 -> 0 | M24: 55 | N24: =C24*M24 -> 0 | O24: 57.5 | P24: =C24*O24 -> 0
B26: Traffic Safety and Management
B28: Road Closures
A30: 1/009 | B30: Erect, maintain and remove all pedestrian & traffic safety measures as per standard drawing 100/1 (Type 1) full closure to facilitate road closures. | C30: ='Series 100 Input'!C30 -> 1 | D30: Day | E30: 629.2 | F30: =C30*E30 -> 629.2 | G30: 795 | H30: =C30*G30 -> 795 | I30: 173.74 | J30: =C30*I30 -> 173.74 | K30: 100 | L30: =C30*K30 -> 100 | M30: 467.5 | N30: =C30*M30 -> 467.5 | O30: 488.75 | P30: =C30*O30 -> 488.75
A32: 1/010 | B32: Erect, maintain and remove all pedestrian & traffic safety measures as per standard drawing 100/1 (Type 2 )half gate to facilitate road closures. | C32: ='Series 100 Input'!C32 -> 0 | D32: Day | E32: 629.2 | F32: =C32*E32 -> 0 | G32: 795 | H32: =C32*G32 -> 0 | I32: 173.74 | J32: =C32*I32 -> 0 | K32: 100 | L32: =C32*K32 -> 0 | M32: 467.5 | N32: =C32*M32 -> 0 | O32: 488.75 | P32: =C32*O32 -> 0
A34: 1/011 | B34: Erect, maintain and remove all pedestrian & traffic safety measures as per standard drawing 100/1 (Type 2A )half gate to facilitate road closures. | C34: ='Series 100 Input'!C34 -> 0 | D34: Day | E34: 629.2 | F34: =C34*E34 -> 0 | G34: 795 | H34: =C34*G34 -> 0 | I34: 173.74 | J34: =C34*I34 -> 0 | K34: 100 | L34: =C34*K34 -> 0 | M34: 467.5 | N34: =C34*M34 -> 0 | O34: 488.75 | P34: =C34*O34 -> 0
A36: 1/012 | B36: Erect, maintain and remove all pedestrian & traffic safety measures as per standard drawing 100/2 (Type 3 )half gate to facilitate road closures. | C36: ='Series 100 Input'!C36 -> 0 | D36: Day | E36: 629.2 | F36: =C36*E36 -> 0 | G36: 795 | H36: =C36*G36 -> 0 | I36: 173.74 | J36: =C36*I36 -> 0 | K36: 100 | L36: =C36*K36 -> 0 | M36: 467.5 | N36: =C36*M36 -> 0 | O36: 488.75 | P36: =C36*O36 -> 0
A38: 1/013 | B38: extra over for item temporary traffic barriers on P.95 of the Safety at Street Works and Road Works - A code of practice booklet | C38: ='Series 100 Input'!C38 -> 0 | D38: Lin.m | E38: 0.3 | F38: =C38*E38 -> 0 | G38: 5 | H38: =C38*G38 -> 0 | I38: 0.59 | J38: =C38*I38 -> 0 | K38: 2 | L38: =C38*K38 -> 0 | M38: 1.1 | N38: =C38*M38 -> 0 | O38: 1.15 | P38: =C38*O38 -> 0
A40: 1/014 | B40: Extra over for traffic management operatives to manage road closure site extents | C40: ='Series 100 Input'!C40 -> 0 | D40: Day | E40: 629.2 | F40: =C40*E40 -> 0 | G40: 220 | H40: =C40*G40 -> 0 | I40: 308.02 | J40: =C40*I40 -> 0 | K40: 240 | L40: =C40*K40 -> 0 | M40: 220 | N40: =C40*M40 -> 0 | O40: 230 | P40: =C40*O40 -> 0
B42: Diversions
A44: 1/015 | B44: Supply of standard temporary signage 1050x750mm (Road Closed 7010.1, Road Ahead Closed 7010.1, Diversion End 2702, Diversion 2702) as per drawing 100/3 | C44: ='Series 100 Input'!C44 -> 0 | D44: no | E44: 2.42 | F44: =C44*E44 -> 0 | G44: 50 | H44: =C44*G44 -> 0 | I44: 0.02 | J44: =C44*I44 -> 0 | K44: 125 | L44: =C44*K44 -> 0 | M44: 467.5 | N44: =C44*M44 -> 0 | O44: 488.75 | P44: =C44*O44 -> 0
A46: 1/016 | B46: Supply of standard temporary signage 1050x450mm (diverted traffic 2703, 2704) as per drawing 100/3 | C46: ='Series 100 Input'!C46 -> 0 | D46: no | E46: 2.42 | F46: =C46*E46 -> 0 | G46: 50 | H46: =C46*G46 -> 0 | I46: 0.02 | J46: =C46*I46 -> 0 | K46: 50 | L46: =C46*K46 -> 0 | M46: 11 | N46: =C46*M46 -> 0 | O46: 11.5 | P46: =C46*O46 -> 0
A48: 1/017 | B48: Supply of non-standard temporary signage 1050x750mm as directed | C48: ='Series 100 Input'!C48 -> 0 | D48: no | E48: 30.25 | F48: =C48*E48 -> 0 | G48: 50 | H48: =C48*G48 -> 0 | I48: 0.02 | J48: =C48*I48 -> 0 | K48: 50 | L48: =C48*K48 -> 0 | M48: 16.5 | N48: =C48*M48 -> 0 | O48: 17.25 | P48: =C48*O48 -> 0
A50: 1/018 | B50: Supply of non-standard temporary signage 1050x450mm as directed | C50: ='Series 100 Input'!C50 -> 0 | D50: no | E50: 30.25 | F50: =C50*E50 -> 0 | G50: 50 | H50: =C50*G50 -> 0 | I50: 0.02 | J50: =C50*I50 -> 0 | K50: 50 | L50: =C50*K50 -> 0 | M50: 16.5 | N50: =C50*M50 -> 0 | O50: 17.25 | P50: =C50*O50 -> 0
A52: 1/019 | B52: Extra over for item temporary1050x750mm signage in frames with extended legs | C52: ='Series 100 Input'!C52 -> 0 | D52: no | E52: 2.42 | F52: =C52*E52 -> 0 | G52: 50 | H52: =C52*G52 -> 0 | I52: 0.02 | J52: =C52*I52 -> 0 | K52: 75 | L52: =C52*K52 -> 0 | M52: 1.1 | N52: =C52*M52 -> 0 | O52: 1.15 | P52: =C52*O52 -> 0
A54: 1/020 | B54: Extra over for item temporary1050x450mm signage in frames with extended legs | C54: ='Series 100 Input'!C54 -> 0 | D54: no | E54: 2.42 | F54: =C54*E54 -> 0 | G54: 50 | H54: =C54*G54 -> 0 | I54: 0.02 | J54: =C54*I54 -> 0 | K54: 75 | L54: =C54*K54 -> 0 | M54: 22 | N54: =C54*M54 -> 0 | O54: 23 | P54: =C54*O54 -> 0
A56: 1/021 | B56: Supply of non-standard temporary signage 1200x1200mm as directed as per Drawing 100/3 (Z series) | C56: ='Series 100 Input'!C56 -> 0 | D56: no | E56: 60.5 | F56: =C56*E56 -> 0 | G56: 50 | H56: =C56*G56 -> 0 | I56: 0.02 | J56: =C56*I56 -> 0 | K56: 80 | L56: =C56*K56 -> 0 | M56: 22 | N56: =C56*M56 -> 0 | O56: 23 | P56: =C56*O56 -> 0
A58: 1/022 | B58: Extra over for item temporary1200x1200mm signage in frames with extended legs | C58: ='Series 100 Input'!C58 -> 0 | D58: No | E58: 2.42 | F58: =C58*E58 -> 0 | G58: 50 | H58: =C58*G58 -> 0 | I58: 0.02 | J58: =C58*I58 -> 0 | K58: 120 | L58: =C58*K58 -> 0 | M58: 22 | N58: =C58*M58 -> 0 | O58: 23 | P58: =C58*O58 -> 0
B60: < 5 mile Diversion
A62: 1/023 | B62: Erection of temporary diversion route as per shown 3.3 on P.37 Chapter 8 Traffic Signs Manual part 1. | C62: ='Series 100 Input'!C62 -> 4 | D62: Item | E62: 393.25 | F62: =C62*E62 -> 1573 | G62: 495 | H62: =C62*G62 -> 1980 | I62: 55.02 | J62: =C62*I62 -> 220.08 | K62: 250 | L62: =C62*K62 -> 1000 | M62: 401.5 | N62: =C62*M62 -> 1606 | O62: 419.75 | P62: =C62*O62 -> 1679
A64: 1/024 | B64: Maintenance of temporary diversion route as shown figure 3.3 on P.37 Chapter 8 Traffic Signs Manual part 1. | C64: ='Series 100 Input'!C64 -> 10 | D64: Day | E64: 121 | F64: =C64*E64 -> 1210 | G64: 500 | H64: =C64*G64 -> 5000 | I64: 440.02 | J64: =C64*I64 -> 4400.2 | K64: 100 | L64: =C64*K64 -> 1000 | M64: 110 | N64: =C64*M64 -> 1100 | O64: 115 | P64: =C64*O64 -> 1150
A66: 1/025 | B66: Removal of temporary diversion route as per shown 3.3 on P.37 Chapter 8 Traffic Signs Manual part 1. | C66: ='Series 100 Input'!C66 -> 4 | D66: item | E66: 393.25 | F66: =C66*E66 -> 1573 | G66: 495 | H66: =C66*G66 -> 1980 | I66: 55.02 | J66: =C66*I66 -> 220.08 | K66: 200 | L66: =C66*K66 -> 800 | M66: 401.5 | N66: =C66*M66 -> 1606 | O66: 419.75 | P66: =C66*O66 -> 1679
B68: 5 - 25 Mile Diversion
A70: 1/026 | B70: Erection of temporary diversion route as per shown 3.3 on P.37 Chapter 8 Traffic Signs Manual part 1. | C70: ='Series 100 Input'!C70 -> 0 | D70: Item | E70: 477.95 | F70: =C70*E70 -> 0 | G70: 495 | H70: =C70*G70 -> 0 | I70: 55.02 | J70: =C70*I70 -> 0 | K70: 300 | L70: =C70*K70 -> 0 | M70: 544.5 | N70: =C70*M70 -> 0 | O70: 569.25 | P70: =C70*O70 -> 0
A72: 1/027 | B72: Maintenance of temporary diversion route as shown figure 3.3 on P.37 Chapter 8 Traffic Signs Manual part 1. | C72: ='Series 100 Input'!C72 -> 0 | D72: Day | E72: 121 | F72: =C72*E72 -> 0 | G72: 495 | H72: =C72*G72 -> 0 | I72: 550.02 | J72: =C72*I72 -> 0 | K72: 125 | L72: =C72*K72 -> 0 | M72: 110 | N72: =C72*M72 -> 0 | O72: 115 | P72: =C72*O72 -> 0
A74: 1/028 | B74: Removal of temporary diversion route as per shown 3.3 on P.37 Chapter 8 Traffic Signs Manual part 1. | C74: ='Series 100 Input'!C74 -> 0 | D74: item | E74: 477.95 | F74: =C74*E74 -> 0 | G74: 495 | H74: =C74*G74 -> 0 | I74: 55.02 | J74: =C74*I74 -> 0 | K74: 200 | L74: =C74*K74 -> 0 | M74: 214.5 | N74: =C74*M74 -> 0 | O74: 224.25 | P74: =C74*O74 -> 0
B76: > 25 Mile Diversion
A78: 1/029 | B78: Erection of temporary diversion route as per shown 3.3 on P.37 Chapter 8 Traffic Signs Manual part 1. | C78: ='Series 100 Input'!C78 -> 0 | D78: Item | E78: 665.5 | F78: =C78*E78 -> 0 | G78: 1500 | H78: =C78*G78 -> 0 | I78: 110.02 | J78: =C78*I78 -> 0 | K78: 350 | L78: =C78*K78 -> 0 | M78: 544.5 | N78: =C78*M78 -> 0 | O78: 569.25 | P78: =C78*O78 -> 0
...

Sheet Series 100 Final
A1: SERIES 100: PRELIMINARIES
A3: Item | B3: Description | C3: Qty | D3: Unit
E4: Tayside Contracts | G4: John McGeady Ltd | I4: Lightways (Contractors) Ltd | K4: Newlay Civil Engineering | M4: T & N Gilmartin (Contractors) Ltd | O4: Tarmac Limited
B6: Temporary Accommodation | E6: Rate | F6: Cost | G6: Rate | H6: Cost | I6: Rate | J6: Cost | K6: Rate | L6: Cost | M6: Rate | N6: Cost | O6: Rate | P6: Cost
A8: 1/001 | B8: Erection of offices and messes for the Contractor (Comply with appendix 0/6) | C8: ='Series 100 Input'!H8 -> 0 | D8: Item | E8: 120 | F8: =C8*E8 -> 0 | G8: 100 | H8: =C8*G8 -> 0 | I8: 0.01 | J8: =C8*I8 -> 0 | K8: 200 | L8: =C8*K8 -> 0 | M8: 500 | N8: =C8*M8 -> 0 | O8: 500 | P8: =C8*O8 -> 0
A10: 1/002 | B10: Servicing of offices and messes for the Contractor (Comply with appendix 0/6) | C10: ='Series 100 Input'!H10 -> 0 | D10: Day | E10: 100 | F10: =C10*E10 -> 0 | G10: 20 | H10: =C10*G10 -> 0 | I10: 41.9 | J10: =C10*I10 -> 0 | K10: 50 | L10: =C10*K10 -> 0 | M10: 250 | N10: =C10*M10 -> 0 | O10: 100 | P10: =C10*O10 -> 0
A12: 1/003 | B12: Dismantling of offices and messes for the Contractor (Comply with appendix 0/6) | C12: ='Series 100 Input'!H12 -> 0 | D12: Item | E12: 120 | F12: =C12*E12 -> 0 | G12: 100 | H12: =C12*G12 -> 0 | I12: 0.01 | J12: =C12*I12 -> 0 | K12: 100 | L12: =C12*K12 -> 0 | M12: 500 | N12: =C12*M12 -> 0 | O12: 500 | P12: =C12*O12 -> 0
A14: 1/004 | B14: Erection of stores and workshops for the Contractor | C14: ='Series 100 Input'!H14 -> 0 | D14: Item | E14: 120 | F14: =C14*E14 -> 0 | G14: 100 | H14: =C14*G14 -> 0 | I14: 287.63 | J14: =C14*I14 -> 0 | K14: 0 | L14: =C14*K14 -> 0 | M14: 500 | N14: =C14*M14 -> 0 | O14: 150 | P14: =C14*O14 -> 0
A16: 1/005 | B16: Servicing of stores and workshops for the Contractor | C16: ='Series 100 Input'!H16 -> 0 | D16: Day | E16: 100 | F16: =C16*E16 -> 0 | G16: 10 | H16: =C16*G16 -> 0 | I16: 0.01 | J16: =C16*I16 -> 0 | K16: 0 | L16: =C16*K16 -> 0 | M16: 50 | N16: =C16*M16 -> 0 | O16: 25 | P16: =C16*O16 -> 0
A18: 1/006 | B18: Dismantling of stores and workshops for the Contractor | C18: ='Series 100 Input'!H18 -> 0 | D18: Item | E18: 120 | F18: =C18*E18 -> 0 | G18: 100 | H18: =C18*G18 -> 0 | I18: 287.63 | J18: =C18*I18 -> 0 | K18: 0 | L18: =C18*K18 -> 0 | M18: 500 | N18: =C18*M18 -> 0 | O18: 150 | P18: =C18*O18 -> 0
B20: Information Boards & Signs
A22: 1/007 | B22: Uplift, place out, maintain and remove Information board as per example on P.23 of the Safety at Street Works and Road Works | C22: ='Series 100 Input'!H22 -> 0 | D22: No | E22: 217.8 | F22: =C22*E22 -> 0 | G22: 10 | H22: =C22*G22 -> 0 | I22: 6.95 | J22: =C22*I22 -> 0 | K22: 25 | L22: =C22*K22 -> 0 | M22: 55 | N22: =C22*M22 -> 0 | O22: 57.5 | P22: =C22*O22 -> 0
A24: 1/008 | B24: Supply, place out, maintain and remove Information sign as described | C24: ='Series 100 Input'!H24 -> 0 | D24: No | E24: 217.8 | F24: =C24*E24 -> 0 | G24: 10 | H24: =C24*G24 -> 0 | I24: 18.45 | J24: =C24*I24 -> 0 | K24: 75 | L24: =C24*K24 -> 0 | M24: 55 | N24: =C24*M24 -> 0 | O24: 57.5 | P24: =C24*O24 -> 0
B26: Traffic Safety and Management
B28: Road Closures
A30: 1/009 | B30: Erect, maintain and remove all pedestrian & traffic safety measures as per standard drawing 100/1 (Type 1) full closure to facilitate road closures. | C30: ='Series 100 Input'!H30 -> 0 | D30: Day | E30: 629.2 | F30: =C30*E30 -> 0 | G30: 795 | H30: =C30*G30 -> 0 | I30: 173.74 | J30: =C30*I30 -> 0 | K30: 100 | L30: =C30*K30 -> 0 | M30: 467.5 | N30: =C30*M30 -> 0 | O30: 488.75 | P30: =C30*O30 -> 0
A32: 1/010 | B32: Erect, maintain and remove all pedestrian & traffic safety measures as per standard drawing 100/1 (Type 2 )half gate to facilitate road closures. | C32: ='Series 100 Input'!H32 -> 0 | D32: Day | E32: 629.2 | F32: =C32*E32 -> 0 | G32: 795 | H32: =C32*G32 -> 0 | I32: 173.74 | J32: =C32*I32 -> 0 | K32: 100 | L32: =C32*K32 -> 0 | M32: 467.5 | N32: =C32*M32 -> 0 | O32: 488.75 | P32: =C32*O32 -> 0
A34: 1/011 | B34: Erect, maintain and remove all pedestrian & traffic safety measures as per standard drawing 100/1 (Type 2A )half gate to facilitate road closures. | C34: ='Series 100 Input'!H34 -> 0 | D34: Day | E34: 629.2 | F34: =C34*E34 -> 0 | G34: 795 | H34: =C34*G34 -> 0 | I34: 173.74 | J34: =C34*I34 -> 0 | K34: 100 | L34: =C34*K34 -> 0 | M34: 467.5 | N34: =C34*M34 -> 0 | O34: 488.75 | P34: =C34*O34 -> 0
A36: 1/012 | B36: Erect, maintain and remove all pedestrian & traffic safety measures as per standard drawing 100/2 (Type 3 )half gate to facilitate road closures. | C36: ='Series 100 Input'!H36 -> 0 | D36: Day | E36: 629.2 | F36: =C36*E36 -> 0 | G36: 795 | H36: =C36*G36 -> 0 | I36: 173.74 | J36: =C36*I36 -> 0 | K36: 100 | L36: =C36*K36 -> 0 | M36: 467.5 | N36: =C36*M36 -> 0 | O36: 488.75 | P36: =C36*O36 -> 0
A38: 1/013 | B38: extra over for item temporary traffic barriers on P.95 of the Safety at Street Works and Road Works - A code of practice booklet | C38: ='Series 100 Input'!H38 -> 0 | D38: Lin.m | E38: 0.3 | F38: =C38*E38 -> 0 | G38: 5 | H38: =C38*G38 -> 0 | I38: 0.59 | J38: =C38*I38 -> 0 | K38: 2 | L38: =C38*K38 -> 0 | M38: 1.1 | N38: =C38*M38 -> 0 | O38: 1.15 | P38: =C38*O38 -> 0
A40: 1/014 | B40: Extra over for traffic management operatives to manage road closure site extents | C40: ='Series 100 Input'!H40 -> 0 | D40: Day | E40: 629.2 | F40: =C40*E40 -> 0 | G40: 220 | H40: =C40*G40 -> 0 | I40: 308.02 | J40: =C40*I40 -> 0 | K40: 240 | L40: =C40*K40 -> 0 | M40: 220 | N40: =C40*M40 -> 0 | O40: 230 | P40: =C40*O40 -> 0
B42: Diversions
A44: 1/015 | B44: Supply of standard temporary signage 1050x750mm (Road Closed 7010.1, Road Ahead Closed 7010.1, Diversion End 2702, Diversion 2702) as per drawing 100/3 | C44: ='Series 100 Input'!H44 -> 0 | D44: no | E44: 2.42 | F44: =C44*E44 -> 0 | G44: 50 | H44: =C44*G44 -> 0 | I44: 0.02 | J44: =C44*I44 -> 0 | K44: 125 | L44: =C44*K44 -> 0 | M44: 467.5 | N44: =C44*M44 -> 0 | O44: 488.75 | P44: =C44*O44 -> 0
A46: 1/016 | B46: Supply of standard temporary signage 1050x450mm (diverted traffic 2703, 2704) as per drawing 100/3 | C46: ='Series 100 Input'!H46 -> 0 | D46: no | E46: 2.42 | F46: =C46*E46 -> 0 | G46: 50 | H46: =C46*G46 -> 0 | I46: 0.02 | J46: =C46*I46 -> 0 | K46: 50 | L46: =C46*K46 -> 0 | M46: 11 | N46: =C46*M46 -> 0 | O46: 11.5 | P46: =C46*O46 -> 0
A48: 1/017 | B48: Supply of non-standard temporary signage 1050x750mm as directed | C48: ='Series 100 Input'!H48 -> 0 | D48: no | E48: 30.25 | F48: =C48*E48 -> 0 | G48: 50 | H48: =C48*G48 -> 0 | I48: 0.02 | J48: =C48*I48 -> 0 | K48: 50 | L48: =C48*K48 -> 0 | M48: 16.5 | N48: =C48*M48 -> 0 | O48: 17.25 | P48: =C48*O48 -> 0
A50: 1/018 | B50: Supply of non-standard temporary signage 1050x450mm as directed | C50: ='Series 100 Input'!H50 -> 0 | D50: no | E50: 30.25 | F50: =C50*E50 -> 0 | G50: 50 | H50: =C50*G50 -> 0 | I50: 0.02 | J50: =C50*I50 -> 0 | K50: 50 | L50: =C50*K50 -> 0 | M50: 16.5 | N50: =C50*M50 -> 0 | O50: 17.25 | P50: =C50*O50 -> 0
A52: 1/019 | B52: Extra over for item temporary1050x750mm signage in frames with extended legs | C52: ='Series 100 Input'!H52 -> 0 | D52: no | E52: 2.42 | F52: =C52*E52 -> 0 | G52: 50 | H52: =C52*G52 -> 0 | I52: 0.02 | J52: =C52*I52 -> 0 | K52: 75 | L52: =C52*K52 -> 0 | M52: 1.1 | N52: =C52*M52 -> 0 | O52: 1.15 | P52: =C52*O52 -> 0
A54: 1/020 | B54: Extra over for item temporary1050x450mm signage in frames with extended legs | C54: ='Series 100 Input'!H54 -> 0 | D54: no | E54: 2.42 | F54: =C54*E54 -> 0 | G54: 50 | H54: =C54*G54 -> 0 | I54: 0.02 | J54: =C54*I54 -> 0 | K54: 75 | L54: =C54*K54 -> 0 | M54: 22 | N54: =C54*M54 -> 0 | O54: 23 | P54: =C54*O54 -> 0
A56: 1/021 | B56: Supply of non-standard temporary signage 1200x1200mm as directed as per Drawing 100/3 (Z series) | C56: ='Series 100 Input'!H56 -> 0 | D56: no | E56: 60.5 | F56: =C56*E56 -> 0 | G56: 50 | H56: =C56*G56 -> 0 | I56: 0.02 | J56: =C56*I56 -> 0 | K56: 80 | L56: =C56*K56 -> 0 | M56: 22 | N56: =C56*M56 -> 0 | O56: 23 | P56: =C56*O56 -> 0
A58: 1/022 | B58: Extra over for item temporary1200x1200mm signage in frames with extended legs | C58: ='Series 100 Input'!H58 -> 0 | D58: No | E58: 2.42 | F58: =C58*E58 -> 0 | G58: 50 | H58: =C58*G58 -> 0 | I58: 0.02 | J58: =C58*I58 -> 0 | K58: 120 | L58: =C58*K58 -> 0 | M58: 22 | N58: =C58*M58 -> 0 | O58: 23 | P58: =C58*O58 -> 0
B60: < 5 mile Diversion
A62: 1/023 | B62: Erection of temporary diversion route as per shown 3.3 on P.37 Chapter 8 Traffic Signs Manual part 1. | C62: ='Series 100 Input'!H62 -> 0 | D62: Item | E62: 393.25 | F62: =C62*E62 -> 0 | G62: 495 | H62: =C62*G62 -> 0 | I62: 55.02 | J62: =C62*I62 -> 0 | K62: 250 | L62: =C62*K62 -> 0 | M62: 401.5 | N62: =C62*M62 -> 0 | O62: 419.75 | P62: =C62*O62 -> 0
A64: 1/024 | B64: Maintenance of temporary diversion route as shown figure 3.3 on P.37 Chapter 8 Traffic Signs Manual part 1. | C64: ='Series 100 Input'!H64 -> 0 | D64: Day | E64: 121 | F64: =C64*E64 -> 0 | G64: 500 | H64: =C64*G64 -> 0 | I64: 440.02 | J64: =C64*I64 -> 0 | K64: 100 | L64: =C64*K64 -> 0 | M64: 110 | N64: =C64*M64 -> 0 | O64: 115 | P64: =C64*O64 -> 0
A66: 1/025 | B66: Removal of temporary diversion route as per shown 3.3 on P.37 Chapter 8 Traffic Signs Manual part 1. | C66: ='Series 100 Input'!H66 -> 0 | D66: item | E66: 393.25 | F66: =C66*E66 -> 0 | G66: 495 | H66: =C66*G66 -> 0 | I66: 55.02 | J66: =C66*I66 -> 0 | K66: 200 | L66: =C66*K66 -> 0 | M66: 401.5 | N66: =C66*M66 -> 0 | O66: 419.75 | P66: =C66*O66 -> 0
B68: 5 - 25 Mile Diversion
A70: 1/026 | B70: Erection of temporary diversion route as per shown 3.3 on P.37 Chapter 8 Traffic Signs Manual part 1. | C70: ='Series 100 Input'!H70 -> 0 | D70: Item | E70: 477.95 | F70: =C70*E70 -> 0 | G70: 495 | H70: =C70*G70 -> 0 | I70: 55.02 | J70: =C70*I70 -> 0 | K70: 300 | L70: =C70*K70 -> 0 | M70: 544.5 | N70: =C70*M70 -> 0 | O70: 569.25 | P70: =C70*O70 -> 0
A72: 1/027 | B72: Maintenance of temporary diversion route as shown figure 3.3 on P.37 Chapter 8 Traffic Signs Manual part 1. | C72: ='Series 100 Input'!H72 -> 0 | D72: Day | E72: 121 | F72: =C72*E72 -> 0 | G72: 495 | H72: =C72*G72 -> 0 | I72: 550.02 | J72: =C72*I72 -> 0 | K72: 125 | L72: =C72*K72 -> 0 | M72: 110 | N72: =C72*M72 -> 0 | O72: 115 | P72: =C72*O72 -> 0
A74: 1/028 | B74: Removal of temporary diversion route as per shown 3.3 on P.37 Chapter 8 Traffic Signs Manual part 1. | C74: ='Series 100 Input'!H74 -> 0 | D74: item | E74: 477.95 | F74: =C74*E74 -> 0 | G74: 495 | H74: =C74*G74 -> 0 | I74: 55.02 | J74: =C74*I74 -> 0 | K74: 200 | L74: =C74*K74 -> 0 | M74: 214.5 | N74: =C74*M74 -> 0 | O74: 224.25 | P74: =C74*O74 -> 0
B76: > 25 Mile Diversion
A78: 1/029 | B78: Erection of temporary diversion route as per shown 3.3 on P.37 Chapter 8 Traffic Signs Manual part 1. | C78: ='Series 100 Input'!H78 -> 0 | D78: Item | E78: 665.5 | F78: =C78*E78 -> 0 | G78: 1500 | H78: =C78*G78 -> 0 | I78: 110.02 | J78: =C78*I78 -> 0 | K78: 350 | L78: =C78*K78 -> 0 | M78: 544.5 | N78: =C78*M78 -> 0 | O78: 569.25 | P78: =C78*O78 -> 0
...

Sheet Series 100 Input
A1: SERIES 100: PRELIMINARIES
A3: Item | B3: Description | C3: Design | E3: Tayside Contracts | H3: Final | J3: TC
C4: Qty | D4: Unit | E4: Rate | F4: Cost | H4: Qty | I4: Unit | J4: Cost
B6: Temporary Accommodation
A8: 1/001 | B8: Erection of offices and messes for the Contractor (Comply with appendix 0/6) | C8: 1 | D8: Item | E8: 120 | F8: =IF('Series 100 Design'!$F8 = 0,,'Series 100 Design'!$F8) -> 120 | I8: Item | J8: =IF('Series 100 Final'!$F8 = 0,,'Series 100 Final'!$F8) -> 0
A10: 1/002 | B10: Servicing of offices and messes for the Contractor (Comply with appendix 0/6) | C10: 10 | D10: Day | E10: 100 | F10: =IF('Series 100 Design'!$F10 = 0,,'Series 100 Design'!$F10) -> 1000 | I10: Day | J10: =IF('Series 100 Final'!$F10 = 0,,'Series 100 Final'!$F10) -> 0
A12: 1/003 | B12: Dismantling of offices and messes for the Contractor (Comply with appendix 0/6) | C12: 1 | D12: Item | E12: 120 | F12: =IF('Series 100 Design'!$F12 = 0,,'Series 100 Design'!$F12) -> 120 | I12: Item | J12: =IF('Series 100 Final'!$F12 = 0,,'Series 100 Final'!$F12) -> 0
A14: 1/004 | B14: Erection of stores and workshops for the Contractor | D14: Item | E14: 120 | F14: =IF('Series 100 Design'!$F14 = 0,,'Series 100 Design'!$F14) -> 0 | I14: Item | J14: =IF('Series 100 Final'!$F14 = 0,,'Series 100 Final'!$F14) -> 0
A16: 1/005 | B16: Servicing of stores and workshops for the Contractor | D16: Day | E16: 100 | F16: =IF('Series 100 Design'!$F16 = 0,,'Series 100 Design'!$F16) -> 0 | I16: Day | J16: =IF('Series 100 Final'!$F16 = 0,,'Series 100 Final'!$F16) -> 0
A18: 1/006 | B18: Dismantling of stores and workshops for the Contractor | D18: Item | E18: 120 | F18: =IF('Series 100 Design'!$F18 = 0,,'Series 100 Design'!$F18) -> 0 | I18: Item | J18: =IF('Series 100 Final'!$F18 = 0,,'Series 100 Final'!$F18) -> 0
B20: Information Boards & Signs
A22: 1/007 | B22: Uplift, place out, maintain and remove Information board as per example on P.23 of the Safety at Street Works and Road Works | D22: No | E22: 217.8 | F22: =IF('Series 100 Design'!$F22 = 0,,'Series 100 Design'!$F22) -> 0 | I22: No | J22: =IF('Series 100 Final'!$F22 = 0,,'Series 100 Final'!$F22) -> 0
A24: 1/008 | B24: Supply, place out, maintain and remove Information sign as described | D24: No | E24: 217.8 | F24: =IF('Series 100 Design'!$F24 = 0,,'Series 100 Design'!$F24) -> 0 | I24: No | J24: =IF('Series 100 Final'!$F24 = 0,,'Series 100 Final'!$F24) -> 0
B26: Traffic Safety and Management
B28: Road Closures
A30: 1/009 | B30: Erect, maintain and remove all pedestrian & traffic safety measures as per standard drawing 100/1 (Type 1) full closure to facilitate road closures. | C30: 1 | D30: Day | E30: 629.2 | F30: =IF('Series 100 Design'!$F30 = 0,,'Series 100 Design'!$F30) -> 629.2 | I30: Day | J30: =IF('Series 100 Final'!$F30 = 0,,'Series 100 Final'!$F30) -> 0
A32: 1/010 | B32: Erect, maintain and remove all pedestrian & traffic safety measures as per standard drawing 100/1 (Type 2 )half gate to facilitate road closures. | D32: Day | E32: 629.2 | F32: =IF('Series 100 Design'!$F32 = 0,,'Series 100 Design'!$F32) -> 0 | I32: Day | J32: =IF('Series 100 Final'!$F32 = 0,,'Series 100 Final'!$F32) -> 0
A34: 1/011 | B34: Erect, maintain and remove all pedestrian & traffic safety measures as per standard drawing 100/1 (Type 2A )half gate to facilitate road closures. | D34: Day | E34: 629.2 | F34: =IF('Series 100 Design'!$F34 = 0,,'Series 100 Design'!$F34) -> 0 | I34: Day | J34: =IF('Series 100 Final'!$F34 = 0,,'Series 100 Final'!$F34) -> 0
A36: 1/012 | B36: Erect, maintain and remove all pedestrian & traffic safety measures as per standard drawing 100/2 (Type 3 )half gate to facilitate road closures. | D36: Day | E36: 629.2 | F36: =IF('Series 100 Design'!$F36 = 0,,'Series 100 Design'!$F36) -> 0 | I36: Day | J36: =IF('Series 100 Final'!$F36 = 0,,'Series 100 Final'!$F36) -> 0
A38: 1/013 | B38: extra over for item temporary traffic barriers on P.95 of the Safety at Street Works and Road Works - A code of practice booklet | D38: Lin.m | E38: 0.3 | F38: =IF('Series 100 Design'!$F38 = 0,,'Series 100 Design'!$F38) -> 0 | I38: Lin.m | J38: =IF('Series 100 Final'!$F38 = 0,,'Series 100 Final'!$F38) -> 0
A40: 1/014 | B40: Extra over for traffic management operatives to manage road closure site extents | D40: Day | E40: 629.2 | F40: =IF('Series 100 Design'!$F40 = 0,,'Series 100 Design'!$F40) -> 0 | I40: Day | J40: =IF('Series 100 Final'!$F40 = 0,,'Series 100 Final'!$F40) -> 0
B42: Diversions
A44: 1/015 | B44: Supply of standard temporary signage 1050x750mm (Road Closed 7010.1, Road Ahead Closed 7010.1, Diversion End 2702, Diversion 2702) as per drawing 100/3 | D44: no | E44: 2.42 | F44: =IF('Series 100 Design'!$F44 = 0,,'Series 100 Design'!$F44) -> 0 | I44: no | J44: =IF('Series 100 Final'!$F44 = 0,,'Series 100 Final'!$F44) -> 0
A46: 1/016 | B46: Supply of standard temporary signage 1050x450mm (diverted traffic 2703, 2704) as per drawing 100/3 | D46: no | E46: 2.42 | F46: =IF('Series 100 Design'!$F46 = 0,,'Series 100 Design'!$F46) -> 0 | I46: no | J46: =IF('Series 100 Final'!$F46 = 0,,'Series 100 Final'!$F46) -> 0
A48: 1/017 | B48: Supply of non-standard temporary signage 1050x750mm as directed | D48: no | E48: 30.25 | F48: =IF('Series 100 Design'!$F48 = 0,,'Series 100 Design'!$F48) -> 0 | I48: no | J48: =IF('Series 100 Final'!$F48 = 0,,'Series 100 Final'!$F48) -> 0
A50: 1/018 | B50: Supply of non-standard temporary signage 1050x450mm as directed | D50: no | E50: 30.25 | F50: =IF('Series 100 Design'!$F50 = 0,,'Series 100 Design'!$F50) -> 0 | I50: no | J50: =IF('Series 100 Final'!$F50 = 0,,'Series 100 Final'!$F50) -> 0
A52: 1/019 | B52: Extra over for item temporary1050x750mm signage in frames with extended legs | D52: no | E52: 2.42 | F52: =IF('Series 100 Design'!$F52 = 0,,'Series 100 Design'!$F52) -> 0 | I52: no | J52: =IF('Series 100 Final'!$F52 = 0,,'Series 100 Final'!$F52) -> 0
A54: 1/020 | B54: Extra over for item temporary1050x450mm signage in frames with extended legs | D54: no | E54: 2.42 | F54: =IF('Series 100 Design'!$F54 = 0,,'Series 100 Design'!$F54) -> 0 | I54: no | J54: =IF('Series 100 Final'!$F54 = 0,,'Series 100 Final'!$F54) -> 0
A56: 1/021 | B56: Supply of non-standard temporary signage 1200x1200mm as directed as per Drawing 100/3 (Z series) | D56: no | E56: 60.5 | F56: =IF('Series 100 Design'!$F56 = 0,,'Series 100 Design'!$F56) -> 0 | I56: no | J56: =IF('Series 100 Final'!$F56 = 0,,'Series 100 Final'!$F56) -> 0
A58: 1/022 | B58: Extra over for item temporary1200x1200mm signage in frames with extended legs | D58: No | E58: 2.42 | F58: =IF('Series 100 Design'!$F58 = 0,,'Series 100 Design'!$F58) -> 0 | I58: No | J58: =IF('Series 100 Final'!$F58 = 0,,'Series 100 Final'!$F58) -> 0
B60: < 5 mile Diversion | F60: =IF('Series 100 Design'!$F60 = 0,,'Series 100 Design'!$F60) -> 0 | J60: =IF('Series 100 Final'!$F60 = 0,,'Series 100 Final'!$F60) -> 0
A62: 1/023 | B62: Erection of temporary diversion route as per shown 3.3 on P.37 Chapter 8 Traffic Signs Manual part 1. | C62: 4 | D62: Item | E62: 393.25 | F62: =IF('Series 100 Design'!$F62 = 0,,'Series 100 Design'!$F62) -> 1573 | I62: Item | J62: =IF('Series 100 Final'!$F62 = 0,,'Series 100 Final'!$F62) -> 0
A64: 1/024 | B64: Maintenance of temporary diversion route as shown figure 3.3 on P.37 Chapter 8 Traffic Signs Manual part 1. | C64: 10 | D64: Day | E64: 121 | F64: =IF('Series 100 Design'!$F64 = 0,,'Series 100 Design'!$F64) -> 1210 | I64: Day | J64: =IF('Series 100 Final'!$F64 = 0,,'Series 100 Final'!$F64) -> 0
A66: 1/025 | B66: Removal of temporary diversion route as per shown 3.3 on P.37 Chapter 8 Traffic Signs Manual part 1. | C66: 4 | D66: item | E66: 393.25 | F66: =IF('Series 100 Design'!$F66 = 0,,'Series 100 Design'!$F66) -> 1573 | I66: item | J66: =IF('Series 100 Final'!$F66 = 0,,'Series 100 Final'!$F66) -> 0
B68: 5 - 25 Mile Diversion | F68: =IF('Series 100 Design'!$F68 = 0,,'Series 100 Design'!$F68) -> 0 | J68: =IF('Series 100 Final'!$F68 = 0,,'Series 100 Final'!$F68) -> 0
A70: 1/026 | B70: Erection of temporary diversion route as per shown 3.3 on P.37 Chapter 8 Traffic Signs Manual part 1. | D70: Item | E70: 477.95 | F70: =IF('Series 100 Design'!$F70 = 0,,'Series 100 Design'!$F70) -> 0 | I70: Item | J70: =IF('Series 100 Final'!$F70 = 0,,'Series 100 Final'!$F70) -> 0
A72: 1/027 | B72: Maintenance of temporary diversion route as shown figure 3.3 on P.37 Chapter 8 Traffic Signs Manual part 1. | D72: Day | E72: 121 | F72: =IF('Series 100 Design'!$F72 = 0,,'Series 100 Design'!$F72) -> 0 | I72: Day | J72: =IF('Series 100 Final'!$F72 = 0,,'Series 100 Final'!$F72) -> 0
A74: 1/028 | B74: Removal of temporary diversion route as per shown 3.3 on P.37 Chapter 8 Traffic Signs Manual part 1. | D74: item | E74: 477.95 | F74: =IF('Series 100 Design'!$F74 = 0,,'Series 100 Design'!$F74) -> 0 | I74: item | J74: =IF('Series 100 Final'!$F74 = 0,,'Series 100 Final'!$F74) -> 0
B76: > 25 Mile Diversion | F76: =IF('Series 100 Design'!$F76 = 0,,'Series 100 Design'!$F76) -> 0 | J76: =IF('Series 100 Final'!$F76 = 0,,'Series 100 Final'!$F76) -> 0
A78: 1/029 | B78: Erection of temporary diversion route as per shown 3.3 on P.37 Chapter 8 Traffic Signs Manual part 1. | D78: Item | E78: 665.5 | F78: =IF('Series 100 Design'!$F78 = 0,,'Series 100 Design'!$F78) -> 0 | I78: Item | J78: =IF('Series 100 Final'!$F78 = 0,,'Series 100 Final'!$F78) -> 0
...

Sheet Series 200 Design
A1: SERIES 200: SITE CLEARANCE
A2: Item | B2: Description | C2: Qty | D2: Unit | E2: Tayside Contracts | I2: John McGeady Ltd | M2: Lightways (Contractors) Ltd | Q2: Newlay Civil Engineering | U2: T & N Gilmartin (Contractors) Ltd | Y2: Tarmac Limited
E3: Band A | F3: Band B | G3: Band C | H3: Cost | I3: Band A | J3: Band B | K3: Band C | L3: Cost | M3: Band A | N3: Band B | O3: Band C | P3: Cost | Q3: Band A | R3: Band B | S3: Band C | T3: Cost | U3: Band A | V3: Band B | W3: Band C | X3: Cost | Y3: Band A | Z3: Band B | AA3: Band C | AB3: Cost
B5: Site Clearance | E5: < 5 | F5: 5 - 20 | G5: > 20 | I5: < 5 | J5: 5 - 20 | K5: > 20 | M5: < 5 | N5: 5 - 20 | O5: > 20 | Q5: < 5 | R5: 5 - 20 | S5: > 20 | U5: < 5 | V5: 5 - 20 | W5: > 20 | Y5: < 5 | Z5: 5 - 20 | AA5: > 20
A7: 2/001 | B7: General site clearance | C7: ='Series 200 Input'!C7 -> 0.3 | D7: Ha | E7: 3000 | F7: 3000 | G7: 3000 | H7: =IF((0=$C7),"",IFERROR(IF($C7<5,$C7*E7,IF(AND(5<=$C7,$C7<=20),$C7*F7,IF($C7>20,$C7*G7,"No Offer"))),"No Offer")) -> 900 | I7: No offer | J7: No offer | K7: No offer | L7: =IF((0=$C7),"",IFERROR(IF($C7<5,$C7*I7,IF(AND(5<=$C7,$C7<=20),$C7*J7,IF($C7>20,$C7*K7,"No Offer"))),"No Offer")) -> No Offer | M7: 1.33 | N7: 1.33 | O7: 1.33 | P7: =IF((0=$C7),"",IFERROR(IF($C7<5,$C7*M7,IF(AND(5<=$C7,$C7<=20),$C7*N7,IF($C7>20,$C7*O7,"No Offer"))),"No Offer")) -> 0.399 | Q7: No offer | R7: No offer | S7: No offer | T7: =IF((0=$C7),"",IFERROR(IF($C7<5,$C7*Q7,IF(AND(5<=$C7,$C7<=20),$C7*R7,IF($C7>20,$C7*S7,"No Offer"))),"No Offer")) -> No Offer | U7: 2400 | V7: 2100 | W7: 1800 | X7: =IF((0=$C7),"",IFERROR(IF($C7<5,$C7*U7,IF(AND(5<=$C7,$C7<=20),$C7*V7,IF($C7>20,$C7*W7,"No Offer"))),"No Offer")) -> 720 | Y7: 1500 | Z7: 1500 | AA7: 1500 | AB7: =IF((0=$C7),"",IFERROR(IF($C7<5,$C7*Y7,IF(AND(5<=$C7,$C7<=20),$C7*Z7,IF($C7>20,$C7*AA7,"No Offer"))),"No Offer")) -> 450
C8: ='Series 200 Input'!C8 -> 0
B9: Take Up or Down and Set Aside for Reuse or Remove to Store off Site | C9: ='Series 200 Input'!C9 -> 0
C10: ='Series 200 Input'!C10 -> 0
B11: Remove to Tip Off Site | C11: ='Series 200 Input'!C11 -> 0
C12: ='Series 200 Input'!C12 -> 0
B13: Slabs | C13: ='Series 200 Input'!C13 -> 0 | E13: < 10 | F13: 10 - 50 | G13: > 50 | I13: < 10 | J13: 10 - 50 | K13: > 50 | M13: < 10 | N13: 10 - 50 | O13: > 50 | Q13: < 10 | R13: 10 - 50 | S13: > 50 | U13: < 10 | V13: 10 - 50 | W13: > 50 | Y13: < 10 | Z13: 10 - 50 | AA13: > 50
C14: ='Series 200 Input'!C14 -> 0
A15: 2/010 | B15: Take up or down and remove to tip off site precast concrete slab paving 50mm thick | C15: ='Series 200 Input'!C15 -> 0 | D15: m2 | E15: 43.15 | F15: 7.13 | G15: 4.45 | H15: =IF((0=$C15),"",IFERROR(IF($C15<10,$C15*E15,IF(AND(10<=$C15,$C15<=50),$C15*F15,IF($C15>50,$C15*G15,"No Offer"))),"No Offer")) | I15: 3 | J15: 3 | K15: 3 | L15: =IF((0=$C15),"",IFERROR(IF($C15<10,$C15*I15,IF(AND(10<=$C15,$C15<=50),$C15*J15,IF($C15>50,$C15*K15,"No Offer"))),"No Offer")) | M15: 7.43 | N15: 7.43 | O15: 7.43 | P15: =IF((0=$C15),"",IFERROR(IF($C15<10,$C15*M15,IF(AND(10<=$C15,$C15<=50),$C15*N15,IF($C15>50,$C15*O15,"No Offer"))),"No Offer")) | Q15: 4 | R15: 4 | S15: 4 | T15: =IF((0=$C15),"",IFERROR(IF($C15<10,$C15*Q15,IF(AND(10<=$C15,$C15<=50),$C15*R15,IF($C15>50,$C15*S15,"No Offer"))),"No Offer")) | U15: 7.8 | V15: 6.37 | W15: 6 | X15: =IF((0=$C15),"",IFERROR(IF($C15<10,$C15*U15,IF(AND(10<=$C15,$C15<=50),$C15*V15,IF($C15>50,$C15*W15,"No Offer"))),"No Offer")) | Y15: No Offer | Z15: No Offer | AA15: No Offer | AB15: =IF((0=$C15),"",IFERROR(IF($C15<10,$C15*Y15,IF(AND(10<=$C15,$C15<=50),$C15*Z15,IF($C15>50,$C15*AA15,"No Offer"))),"No Offer"))
C16: ='Series 200 Input'!C16 -> 0
A17: 2/011 | B17: Take up or down and remove to tip off site precast concrete slab paving 65mm thick | C17: ='Series 200 Input'!C17 -> 0 | D17: m2 | E17: 43.15 | F17: 7.13 | G17: 5.34 | H17: =IF((0=$C17),"",IFERROR(IF($C17<10,$C17*E17,IF(AND(10<=$C17,$C17<=50),$C17*F17,IF($C17>50,$C17*G17,"No Offer"))),"No Offer")) | I17: 3 | J17: 3 | K17: 3 | L17: =IF((0=$C17),"",IFERROR(IF($C17<10,$C17*I17,IF(AND(10<=$C17,$C17<=50),$C17*J17,IF($C17>50,$C17*K17,"No Offer"))),"No Offer")) | M17: 9.32 | N17: 9.32 | O17: 9.32 | P17: =IF((0=$C17),"",IFERROR(IF($C17<10,$C17*M17,IF(AND(10<=$C17,$C17<=50),$C17*N17,IF($C17>50,$C17*O17,"No Offer"))),"No Offer")) | Q17: 4 | R17: 4 | S17: 4 | T17: =IF((0=$C17),"",IFERROR(IF($C17<10,$C17*Q17,IF(AND(10<=$C17,$C17<=50),$C17*R17,IF($C17>50,$C17*S17,"No Offer"))),"No Offer")) | U17: 9 | V17: 7.8 | W17: 7.2 | X17: =IF((0=$C17),"",IFERROR(IF($C17<10,$C17*U17,IF(AND(10<=$C17,$C17<=50),$C17*V17,IF($C17>50,$C17*W17,"No Offer"))),"No Offer")) | Y17: No Offer | Z17: No Offer | AA17: No Offer | AB17: =IF((0=$C17),"",IFERROR(IF($C17<10,$C17*Y17,IF(AND(10<=$C17,$C17<=50),$C17*Z17,IF($C17>50,$C17*AA17,"No Offer"))),"No Offer"))
C18: ='Series 200 Input'!C18 -> 0
A19: 2/012 | B19: Take up or down and remove to tip off site precast concrete tactile paving slab paving 50mm thick | C19: ='Series 200 Input'!C19 -> 0 | D19: m2 | E19: 43.15 | F19: 10.68 | G19: 10.68 | H19: =IF((0=$C19),"",IFERROR(IF($C19<10,$C19*E19,IF(AND(10<=$C19,$C19<=50),$C19*F19,IF($C19>50,$C19*G19,"No Offer"))),"No Offer")) | I19: 3 | J19: 3 | K19: 3 | L19: =IF((0=$C19),"",IFERROR(IF($C19<10,$C19*I19,IF(AND(10<=$C19,$C19<=50),$C19*J19,IF($C19>50,$C19*K19,"No Offer"))),"No Offer")) | M19: 7.43 | N19: 7.43 | O19: 7.43 | P19: =IF((0=$C19),"",IFERROR(IF($C19<10,$C19*M19,IF(AND(10<=$C19,$C19<=50),$C19*N19,IF($C19>50,$C19*O19,"No Offer"))),"No Offer")) | Q19: 4 | R19: 4 | S19: 4 | T19: =IF((0=$C19),"",IFERROR(IF($C19<10,$C19*Q19,IF(AND(10<=$C19,$C19<=50),$C19*R19,IF($C19>50,$C19*S19,"No Offer"))),"No Offer")) | U19: 7.8 | V19: 6.37 | W19: 6 | X19: =IF((0=$C19),"",IFERROR(IF($C19<10,$C19*U19,IF(AND(10<=$C19,$C19<=50),$C19*V19,IF($C19>50,$C19*W19,"No Offer"))),"No Offer")) | Y19: No Offer | Z19: No Offer | AA19: No Offer | AB19: =IF((0=$C19),"",IFERROR(IF($C19<10,$C19*Y19,IF(AND(10<=$C19,$C19<=50),$C19*Z19,IF($C19>50,$C19*AA19,"No Offer"))),"No Offer"))
C20: ='Series 200 Input'!C20 -> 0
A21: 2/013 | B21: Take up or down and remove to tip off site precast concrete tactile paving slab paving 65mm thick | C21: ='Series 200 Input'!C21 -> 0 | D21: m2 | E21: 43.15 | F21: 11.87 | G21: 11.87 | H21: =IF((0=$C21),"",IFERROR(IF($C21<10,$C21*E21,IF(AND(10<=$C21,$C21<=50),$C21*F21,IF($C21>50,$C21*G21,"No Offer"))),"No Offer")) | I21: 3 | J21: 3 | K21: 3 | L21: =IF((0=$C21),"",IFERROR(IF($C21<10,$C21*I21,IF(AND(10<=$C21,$C21<=50),$C21*J21,IF($C21>50,$C21*K21,"No Offer"))),"No Offer")) | M21: 9.32 | N21: 9.32 | O21: 9.32 | P21: =IF((0=$C21),"",IFERROR(IF($C21<10,$C21*M21,IF(AND(10<=$C21,$C21<=50),$C21*N21,IF($C21>50,$C21*O21,"No Offer"))),"No Offer")) | Q21: 4 | R21: 4 | S21: 4 | T21: =IF((0=$C21),"",IFERROR(IF($C21<10,$C21*Q21,IF(AND(10<=$C21,$C21<=50),$C21*R21,IF($C21>50,$C21*S21,"No Offer"))),"No Offer")) | U21: 9 | V21: 7.8 | W21: 7.2 | X21: =IF((0=$C21),"",IFERROR(IF($C21<10,$C21*U21,IF(AND(10<=$C21,$C21<=50),$C21*V21,IF($C21>50,$C21*W21,"No Offer"))),"No Offer")) | Y21: No Offer | Z21: No Offer | AA21: No Offer | AB21: =IF((0=$C21),"",IFERROR(IF($C21<10,$C21*Y21,IF(AND(10<=$C21,$C21<=50),$C21*Z21,IF($C21>50,$C21*AA21,"No Offer"))),"No Offer"))
C22: ='Series 200 Input'!C22 -> 0
A23: 2/014 | B23: Take up or down and remove to tip off site precast concrete hazard paving slab paving 50mm thick | C23: ='Series 200 Input'!C23 -> 0 | D23: m2 | E23: 43.15 | F23: 10.68 | G23: 10.68 | H23: =IF((0=$C23),"",IFERROR(IF($C23<10,$C23*E23,IF(AND(10<=$C23,$C23<=50),$C23*F23,IF($C23>50,$C23*G23,"No Offer"))),"No Offer")) | I23: 3 | J23: 3 | K23: 3 | L23: =IF((0=$C23),"",IFERROR(IF($C23<10,$C23*I23,IF(AND(10<=$C23,$C23<=50),$C23*J23,IF($C23>50,$C23*K23,"No Offer"))),"No Offer")) | M23: 7.43 | N23: 7.43 | O23: 7.43 | P23: =IF((0=$C23),"",IFERROR(IF($C23<10,$C23*M23,IF(AND(10<=$C23,$C23<=50),$C23*N23,IF($C23>50,$C23*O23,"No Offer"))),"No Offer")) | Q23: 4 | R23: 4 | S23: 4 | T23: =IF((0=$C23),"",IFERROR(IF($C23<10,$C23*Q23,IF(AND(10<=$C23,$C23<=50),$C23*R23,IF($C23>50,$C23*S23,"No Offer"))),"No Offer")) | U23: 7.8 | V23: 6.37 | W23: 6 | X23: =IF((0=$C23),"",IFERROR(IF($C23<10,$C23*U23,IF(AND(10<=$C23,$C23<=50),$C23*V23,IF($C23>50,$C23*W23,"No Offer"))),"No Offer")) | Y23: No Offer | Z23: No Offer | AA23: No Offer | AB23: =IF((0=$C23),"",IFERROR(IF($C23<10,$C23*Y23,IF(AND(10<=$C23,$C23<=50),$C23*Z23,IF($C23>50,$C23*AA23,"No Offer"))),"No Offer"))
C24: ='Series 200 Input'!C24 -> 0
A25: 2/015 | B25: Take up or down and remove to tip off site precast concrete hazard paving slab paving 65mm thick | C25: ='Series 200 Input'!C25 -> 0 | D25: m2 | E25: 43.15 | F25: 11.87 | G25: 11.87 | H25: =IF((0=$C25),"",IFERROR(IF($C25<10,$C25*E25,IF(AND(10<=$C25,$C25<=50),$C25*F25,IF($C25>50,$C25*G25,"No Offer"))),"No Offer")) | I25: 3 | J25: 3 | K25: 3 | L25: =IF((0=$C25),"",IFERROR(IF($C25<10,$C25*I25,IF(AND(10<=$C25,$C25<=50),$C25*J25,IF($C25>50,$C25*K25,"No Offer"))),"No Offer")) | M25: 9.32 | N25: 9.32 | O25: 9.32 | P25: =IF((0=$C25),"",IFERROR(IF($C25<10,$C25*M25,IF(AND(10<=$C25,$C25<=50),$C25*N25,IF($C25>50,$C25*O25,"No Offer"))),"No Offer")) | Q25: 4 | R25: 4 | S25: 4 | T25: =IF((0=$C25),"",IFERROR(IF($C25<10,$C25*Q25,IF(AND(10<=$C25,$C25<=50),$C25*R25,IF($C25>50,$C25*S25,"No Offer"))),"No Offer")) | U25: 9 | V25: 7.8 | W25: 7.2 | X25: =IF((0=$C25),"",IFERROR(IF($C25<10,$C25*U25,IF(AND(10<=$C25,$C25<=50),$C25*V25,IF($C25>50,$C25*W25,"No Offer"))),"No Offer")) | Y25: No Offer | Z25: No Offer | AA25: No Offer | AB25: =IF((0=$C25),"",IFERROR(IF($C25<10,$C25*Y25,IF(AND(10<=$C25,$C25<=50),$C25*Z25,IF($C25>50,$C25*AA25,"No Offer"))),"No Offer"))
C26: ='Series 200 Input'!C26 -> 0
A27: 2/016 | B27: Take up or down and remove to tip off site natural stone slab paving 50mm thick | C27: ='Series 200 Input'!C27 -> 0 | D27: m2 | E27: 43.15 | F27: 10.68 | G27: 10.68 | H27: =IF((0=$C27),"",IFERROR(IF($C27<10,$C27*E27,IF(AND(10<=$C27,$C27<=50),$C27*F27,IF($C27>50,$C27*G27,"No Offer"))),"No Offer")) | I27: 3 | J27: 3 | K27: 3 | L27: =IF((0=$C27),"",IFERROR(IF($C27<10,$C27*I27,IF(AND(10<=$C27,$C27<=50),$C27*J27,IF($C27>50,$C27*K27,"No Offer"))),"No Offer")) | M27: 10.49 | N27: 10.49 | O27: 10.49 | P27: =IF((0=$C27),"",IFERROR(IF($C27<10,$C27*M27,IF(AND(10<=$C27,$C27<=50),$C27*N27,IF($C27>50,$C27*O27,"No Offer"))),"No Offer")) | Q27: 4 | R27: 4 | S27: 4 | T27: =IF((0=$C27),"",IFERROR(IF($C27<10,$C27*Q27,IF(AND(10<=$C27,$C27<=50),$C27*R27,IF($C27>50,$C27*S27,"No Offer"))),"No Offer")) | U27: 9 | V27: 7.8 | W27: 7.2 | X27: =IF((0=$C27),"",IFERROR(IF($C27<10,$C27*U27,IF(AND(10<=$C27,$C27<=50),$C27*V27,IF($C27>50,$C27*W27,"No Offer"))),"No Offer")) | Y27: No Offer | Z27: No Offer | AA27: No Offer | AB27: =IF((0=$C27),"",IFERROR(IF($C27<10,$C27*Y27,IF(AND(10<=$C27,$C27<=50),$C27*Z27,IF($C27>50,$C27*AA27,"No Offer"))),"No Offer"))
C28: ='Series 200 Input'!C28 -> 0
A29: 2/017 | B29: Take up or down and remove to tip off site natural stone slab paving 60mm thick | C29: ='Series 200 Input'!C29 -> 0 | D29: m2 | E29: 43.15 | F29: 11.87 | G29: 11.87 | H29: =IF((0=$C29),"",IFERROR(IF($C29<10,$C29*E29,IF(AND(10<=$C29,$C29<=50),$C29*F29,IF($C29>50,$C29*G29,"No Offer"))),"No Offer")) | I29: 3 | J29: 3 | K29: 3 | L29: =IF((0=$C29),"",IFERROR(IF($C29<10,$C29*I29,IF(AND(10<=$C29,$C29<=50),$C29*J29,IF($C29>50,$C29*K29,"No Offer"))),"No Offer")) | M29: 10.76 | N29: 10.76 | O29: 10.76 | P29: =IF((0=$C29),"",IFERROR(IF($C29<10,$C29*M29,IF(AND(10<=$C29,$C29<=50),$C29*N29,IF($C29>50,$C29*O29,"No Offer"))),"No Offer")) | Q29: 4 | R29: 4 | S29: 4 | T29: =IF((0=$C29),"",IFERROR(IF($C29<10,$C29*Q29,IF(AND(10<=$C29,$C29<=50),$C29*R29,IF($C29>50,$C29*S29,"No Offer"))),"No Offer")) | U29: 9.5 | V29: 7.85 | W29: 7.4 | X29: =IF((0=$C29),"",IFERROR(IF($C29<10,$C29*U29,IF(AND(10<=$C29,$C29<=50),$C29*V29,IF($C29>50,$C29*W29,"No Offer"))),"No Offer")) | Y29: No Offer | Z29: No Offer | AA29: No Offer | AB29: =IF((0=$C29),"",IFERROR(IF($C29<10,$C29*Y29,IF(AND(10<=$C29,$C29<=50),$C29*Z29,IF($C29>50,$C29*AA29,"No Offer"))),"No Offer"))
C30: ='Series 200 Input'!C30 -> 0
A31: 2/018 | B31: Take up or down and remove to tip off site natural stone slab paving 70mm thick | C31: ='Series 200 Input'!C31 -> 0 | D31: m2 | E31: 57.46 | F31: 28.56 | G31: 28.56 | H31: =IF((0=$C31),"",IFERROR(IF($C31<10,$C31*E31,IF(AND(10<=$C31,$C31<=50),$C31*F31,IF($C31>50,$C31*G31,"No Offer"))),"No Offer")) | I31: 3 | J31: 3 | K31: 3 | L31: =IF((0=$C31),"",IFERROR(IF($C31<10,$C31*I31,IF(AND(10<=$C31,$C31<=50),$C31*J31,IF($C31>50,$C31*K31,"No Offer"))),"No Offer")) | M31: 11.02 | N31: 11.02 | O31: 11.02 | P31: =IF((0=$C31),"",IFERROR(IF($C31<10,$C31*M31,IF(AND(10<=$C31,$C31<=50),$C31*N31,IF($C31>50,$C31*O31,"No Offer"))),"No Offer")) | Q31: 4 | R31: 4 | S31: 4 | T31: =IF((0=$C31),"",IFERROR(IF($C31<10,$C31*Q31,IF(AND(10<=$C31,$C31<=50),$C31*R31,IF($C31>50,$C31*S31,"No Offer"))),"No Offer")) | U31: 10 | V31: 7.91 | W31: 7.68 | X31: =IF((0=$C31),"",IFERROR(IF($C31<10,$C31*U31,IF(AND(10<=$C31,$C31<=50),$C31*V31,IF($C31>50,$C31*W31,"No Offer"))),"No Offer")) | Y31: No Offer | Z31: No Offer | AA31: No Offer | AB31: =IF((0=$C31),"",IFERROR(IF($C31<10,$C31*Y31,IF(AND(10<=$C31,$C31<=50),$C31*Z31,IF($C31>50,$C31*AA31,"No Offer"))),"No Offer"))
C32: ='Series 200 Input'!C32 -> 0
B33: Block Paving / Setts | C33: ='Series 200 Input'!C33 -> 0 | E33: < 10 | F33: 10 - 50 | G33: > 50 | I33: < 10 | J33: 10 - 50 | K33: > 50 | M33: < 10 | N33: 10 - 50 | O33: > 50 | Q33: < 10 | R33: 10 - 50 | S33: > 50 | U33: < 10 | V33: 10 - 50 | W33: > 50 | Y33: < 10 | Z33: 10 - 50 | AA33: > 50
C34: ='Series 200 Input'!C34 -> 0
A35: 2/020 | B35: Take up or down and remove to tip off site block paving 50mm thick | C35: ='Series 200 Input'!C35 -> 0 | D35: m2 | E35: 43.15 | F35: 7.13 | G35: 4.45 | H35: =IF((0=$C35),"",IFERROR(IF($C35<10,$C35*E35,IF(AND(10<=$C35,$C35<=50),$C35*F35,IF($C35>50,$C35*G35,"No Offer"))),"No Offer")) | I35: 3 | J35: 3 | K35: 3 | L35: =IF((0=$C35),"",IFERROR(IF($C35<10,$C35*I35,IF(AND(10<=$C35,$C35<=50),$C35*J35,IF($C35>50,$C35*K35,"No Offer"))),"No Offer")) | M35: 7.45 | N35: 7.45 | O35: 7.45 | P35: =IF((0=$C35),"",IFERROR(IF($C35<10,$C35*M35,IF(AND(10<=$C35,$C35<=50),$C35*N35,IF($C35>50,$C35*O35,"No Offer"))),"No Offer")) | Q35: 6 | R35: 6 | S35: 6 | T35: =IF((0=$C35),"",IFERROR(IF($C35<10,$C35*Q35,IF(AND(10<=$C35,$C35<=50),$C35*R35,IF($C35>50,$C35*S35,"No Offer"))),"No Offer")) | U35: 9.5 | V35: 7.38 | W35: 7.2 | X35: =IF((0=$C35),"",IFERROR(IF($C35<10,$C35*U35,IF(AND(10<=$C35,$C35<=50),$C35*V35,IF($C35>50,$C35*W35,"No Offer"))),"No Offer")) | Y35: No Offer | Z35: No Offer | AA35: No Offer | AB35: =IF((0=$C35),"",IFERROR(IF($C35<10,$C35*Y35,IF(AND(10<=$C35,$C35<=50),$C35*Z35,IF($C35>50,$C35*AA35,"No Offer"))),"No Offer"))
C36: ='Series 200 Input'!C36 -> 0
A37: 2/021 | B37: Take up or down and remove to tip off site block paving 60mm thick | C37: ='Series 200 Input'!C37 -> 0 | D37: m2 | E37: 43.15 | F37: 7.13 | G37: 4.45 | H37: =IF((0=$C37),"",IFERROR(IF($C37<10,$C37*E37,IF(AND(10<=$C37,$C37<=50),$C37*F37,IF($C37>50,$C37*G37,"No Offer"))),"No Offer")) | I37: 3 | J37: 3 | K37: 3 | L37: =IF((0=$C37),"",IFERROR(IF($C37<10,$C37*I37,IF(AND(10<=$C37,$C37<=50),$C37*J37,IF($C37>50,$C37*K37,"No Offer"))),"No Offer")) | M37: 7.71 | N37: 7.71 | O37: 7.71 | P37: =IF((0=$C37),"",IFERROR(IF($C37<10,$C37*M37,IF(AND(10<=$C37,$C37<=50),$C37*N37,IF($C37>50,$C37*O37,"No Offer"))),"No Offer")) | Q37: 6 | R37: 6 | S37: 6 | T37: =IF((0=$C37),"",IFERROR(IF($C37<10,$C37*Q37,IF(AND(10<=$C37,$C37<=50),$C37*R37,IF($C37>50,$C37*S37,"No Offer"))),"No Offer")) | U37: 9.6 | V37: 7.68 | W37: 7.5 | X37: =IF((0=$C37),"",IFERROR(IF($C37<10,$C37*U37,IF(AND(10<=$C37,$C37<=50),$C37*V37,IF($C37>50,$C37*W37,"No Offer"))),"No Offer")) | Y37: No Offer | Z37: No Offer | AA37: No Offer | AB37: =IF((0=$C37),"",IFERROR(IF($C37<10,$C37*Y37,IF(AND(10<=$C37,$C37<=50),$C37*Z37,IF($C37>50,$C37*AA37,"No Offer"))),"No Offer"))
C38: ='Series 200 Input'!C38 -> 0
A39: 2/022 | B39: Take up or down and remove to tip off site block paving 65mm thick | C39: ='Series 200 Input'!C39 -> 0 | D39: m2 | E39: 43.15 | F39: 7.13 | G39: 4.45 | H39: =IF((0=$C39),"",IFERROR(IF($C39<10,$C39*E39,IF(AND(10<=$C39,$C39<=50),$C39*F39,IF($C39>50,$C39*G39,"No Offer"))),"No Offer")) | I39: 3 | J39: 3 | K39: 3 | L39: =IF((0=$C39),"",IFERROR(IF($C39<10,$C39*I39,IF(AND(10<=$C39,$C39<=50),$C39*J39,IF($C39>50,$C39*K39,"No Offer"))),"No Offer")) | M39: 7.85 | N39: 7.85 | O39: 7.85 | P39: =IF((0=$C39),"",IFERROR(IF($C39<10,$C39*M39,IF(AND(10<=$C39,$C39<=50),$C39*N39,IF($C39>50,$C39*O39,"No Offer"))),"No Offer")) | Q39: 6 | R39: 6 | S39: 6 | T39: =IF((0=$C39),"",IFERROR(IF($C39<10,$C39*Q39,IF(AND(10<=$C39,$C39<=50),$C39*R39,IF($C39>50,$C39*S39,"No Offer"))),"No Offer")) | U39: 9.75 | V39: 7.83 | W39: 7.65 | X39: =IF((0=$C39),"",IFERROR(IF($C39<10,$C39*U39,IF(AND(10<=$C39,$C39<=50),$C39*V39,IF($C39>50,$C39*W39,"No Offer"))),"No Offer")) | Y39: No Offer | Z39: No Offer | AA39: No Offer | AB39: =IF((0=$C39),"",IFERROR(IF($C39<10,$C39*Y39,IF(AND(10<=$C39,$C39<=50),$C39*Z39,IF($C39>50,$C39*AA39,"No Offer"))),"No Offer"))
C40: ='Series 200 Input'!C40 -> 0
A41: 2/023 | B41: Take up or down and remove to tip off site block paving 80mm thick | C41: ='Series 200 Input'!C41 -> 0 | D41: m2 | E41: 43.15 | F41: 7.13 | G41: 5.34 | H41: =IF((0=$C41),"",IFERROR(IF($C41<10,$C41*E41,IF(AND(10<=$C41,$C41<=50),$C41*F41,IF($C41>50,$C41*G41,"No Offer"))),"No Offer")) | I41: 3 | J41: 3 | K41: 3 | L41: =IF((0=$C41),"",IFERROR(IF($C41<10,$C41*I41,IF(AND(10<=$C41,$C41<=50),$C41*J41,IF($C41>50,$C41*K41,"No Offer"))),"No Offer")) | M41: 8.25 | N41: 8.25 | O41: 8.25 | P41: =IF((0=$C41),"",IFERROR(IF($C41<10,$C41*M41,IF(AND(10<=$C41,$C41<=50),$C41*N41,IF($C41>50,$C41*O41,"No Offer"))),"No Offer")) | Q41: 6 | R41: 6 | S41: 6 | T41: =IF((0=$C41),"",IFERROR(IF($C41<10,$C41*Q41,IF(AND(10<=$C41,$C41<=50),$C41*R41,IF($C41>50,$C41*S41,"No Offer"))),"No Offer")) | U41: 10.2 | V41: 8.28 | W41: 8.1 | X41: =IF((0=$C41),"",IFERROR(IF($C41<10,$C41*U41,IF(AND(10<=$C41,$C41<=50),$C41*V41,IF($C41>50,$C41*W41,"No Offer"))),"No Offer")) | Y41: No Offer | Z41: No Offer | AA41: No Offer | AB41: =IF((0=$C41),"",IFERROR(IF($C41<10,$C41*Y41,IF(AND(10<=$C41,$C41<=50),$C41*Z41,IF($C41>50,$C41*AA41,"No Offer"))),"No Offer"))
C42: ='Series 200 Input'!C42 -> 0
...

Sheet Series 200 Final
A1: SERIES 200: SITE CLEARANCE
A2: Item | B2: Description | C2: Qty | D2: Unit | E2: Tayside Contracts | I2: John McGeady Ltd | M2: Lightways (Contractors) Ltd | Q2: Newlay Civil Engineering | U2: T & N Gilmartin (Contractors) Ltd | Y2: Tarmac Limited
E3: Band A | F3: Band B | G3: Band C | H3: Cost | I3: Band A | J3: Band B | K3: Band C | L3: Cost | M3: Band A | N3: Band B | O3: Band C | P3: Cost | Q3: Band A | R3: Band B | S3: Band C | T3: Cost | U3: Band A | V3: Band B | W3: Band C | X3: Cost | Y3: Band A | Z3: Band B | AA3: Band C | AB3: Cost
B5: Site Clearance | E5: < 5 | F5: 5 - 20 | G5: > 20 | I5: < 5 | J5: 5 - 20 | K5: > 20 | M5: < 5 | N5: 5 - 20 | O5: > 20 | Q5: < 5 | R5: 5 - 20 | S5: > 20 | U5: < 5 | V5: 5 - 20 | W5: > 20 | Y5: < 5 | Z5: 5 - 20 | AA5: > 20
A7: 2/001 | B7: General site clearance | C7: ='Series 200 Input'!J7 -> 0 | D7: Ha | E7: 3000 | F7: 3000 | G7: 3000 | H7: =IF((0=$C7),"",IFERROR(IF($C7<5,$C7*E7,IF(AND(5<=$C7,$C7<=20),$C7*F7,IF($C7>20,$C7*G7,"No Offer"))),"No Offer")) | I7: No offer | J7: No offer | K7: No offer | L7: =IF((0=$C7),"",IFERROR(IF($C7<5,$C7*I7,IF(AND(5<=$C7,$C7<=20),$C7*J7,IF($C7>20,$C7*K7,"No Offer"))),"No Offer")) | M7: 1.33 | N7: 1.33 | O7: 1.33 | P7: =IF((0=$C7),"",IFERROR(IF($C7<5,$C7*M7,IF(AND(5<=$C7,$C7<=20),$C7*N7,IF($C7>20,$C7*O7,"No Offer"))),"No Offer")) | Q7: No offer | R7: No offer | S7: No offer | T7: =IF((0=$C7),"",IFERROR(IF($C7<5,$C7*Q7,IF(AND(5<=$C7,$C7<=20),$C7*R7,IF($C7>20,$C7*S7,"No Offer"))),"No Offer")) | U7: 2400 | V7: 2100 | W7: 1800 | X7: =IF((0=$C7),"",IFERROR(IF($C7<5,$C7*U7,IF(AND(5<=$C7,$C7<=20),$C7*V7,IF($C7>20,$C7*W7,"No Offer"))),"No Offer")) | Y7: 1500 | Z7: 1500 | AA7: 1500 | AB7: =IF((0=$C7),"",IFERROR(IF($C7<5,$C7*Y7,IF(AND(5<=$C7,$C7<=20),$C7*Z7,IF($C7>20,$C7*AA7,"No Offer"))),"No Offer"))
C8: ='Series 200 Input'!J8 -> 0
B9: Take Up or Down and Set Aside for Reuse or Remove to Store off Site | C9: ='Series 200 Input'!J9 -> 0
C10: ='Series 200 Input'!J10 -> 0
B11: Remove to Tip Off Site | C11: ='Series 200 Input'!J11 -> 0
C12: ='Series 200 Input'!J12 -> 0
B13: Slabs | C13: ='Series 200 Input'!J13 -> 0 | E13: < 10 | F13: 10 - 50 | G13: > 50 | I13: < 10 | J13: 10 - 50 | K13: > 50 | M13: < 10 | N13: 10 - 50 | O13: > 50 | Q13: < 10 | R13: 10 - 50 | S13: > 50 | U13: < 10 | V13: 10 - 50 | W13: > 50 | Y13: < 10 | Z13: 10 - 50 | AA13: > 50
C14: ='Series 200 Input'!J14 -> 0
A15: 2/010 | B15: Take up or down and remove to tip off site precast concrete slab paving 50mm thick | C15: ='Series 200 Input'!J15 -> 0 | D15: m2 | E15: 43.15 | F15: 7.13 | G15: 4.45 | H15: =IF((0=$C15),"",IFERROR(IF($C15<10,$C15*E15,IF(AND(10<=$C15,$C15<=50),$C15*F15,IF($C15>50,$C15*G15,"No Offer"))),"No Offer")) | I15: 3 | J15: 3 | K15: 3 | L15: =IF((0=$C15),"",IFERROR(IF($C15<10,$C15*I15,IF(AND(10<=$C15,$C15<=50),$C15*J15,IF($C15>50,$C15*K15,"No Offer"))),"No Offer")) | M15: 7.43 | N15: 7.43 | O15: 7.43 | P15: =IF((0=$C15),"",IFERROR(IF($C15<10,$C15*M15,IF(AND(10<=$C15,$C15<=50),$C15*N15,IF($C15>50,$C15*O15,"No Offer"))),"No Offer")) | Q15: 4 | R15: 4 | S15: 4 | T15: =IF((0=$C15),"",IFERROR(IF($C15<10,$C15*Q15,IF(AND(10<=$C15,$C15<=50),$C15*R15,IF($C15>50,$C15*S15,"No Offer"))),"No Offer")) | U15: 7.8 | V15: 6.37 | W15: 6 | X15: =IF((0=$C15),"",IFERROR(IF($C15<10,$C15*U15,IF(AND(10<=$C15,$C15<=50),$C15*V15,IF($C15>50,$C15*W15,"No Offer"))),"No Offer")) | Y15: No Offer | Z15: No Offer | AA15: No Offer | AB15: =IF((0=$C15),"",IFERROR(IF($C15<10,$C15*Y15,IF(AND(10<=$C15,$C15<=50),$C15*Z15,IF($C15>50,$C15*AA15,"No Offer"))),"No Offer"))
C16: ='Series 200 Input'!J16 -> 0
A17: 2/011 | B17: Take up or down and remove to tip off site precast concrete slab paving 65mm thick | C17: ='Series 200 Input'!J17 -> 0 | D17: m2 | E17: 43.15 | F17: 7.13 | G17: 5.34 | H17: =IF((0=$C17),"",IFERROR(IF($C17<10,$C17*E17,IF(AND(10<=$C17,$C17<=50),$C17*F17,IF($C17>50,$C17*G17,"No Offer"))),"No Offer")) | I17: 3 | J17: 3 | K17: 3 | L17: =IF((0=$C17),"",IFERROR(IF($C17<10,$C17*I17,IF(AND(10<=$C17,$C17<=50),$C17*J17,IF($C17>50,$C17*K17,"No Offer"))),"No Offer")) | M17: 9.32 | N17: 9.32 | O17: 9.32 | P17: =IF((0=$C17),"",IFERROR(IF($C17<10,$C17*M17,IF(AND(10<=$C17,$C17<=50),$C17*N17,IF($C17>50,$C17*O17,"No Offer"))),"No Offer")) | Q17: 4 | R17: 4 | S17: 4 | T17: =IF((0=$C17),"",IFERROR(IF($C17<10,$C17*Q17,IF(AND(10<=$C17,$C17<=50),$C17*R17,IF($C17>50,$C17*S17,"No Offer"))),"No Offer")) | U17: 9 | V17: 7.8 | W17: 7.2 | X17: =IF((0=$C17),"",IFERROR(IF($C17<10,$C17*U17,IF(AND(10<=$C17,$C17<=50),$C17*V17,IF($C17>50,$C17*W17,"No Offer"))),"No Offer")) | Y17: No Offer | Z17: No Offer | AA17: No Offer | AB17: =IF((0=$C17),"",IFERROR(IF($C17<10,$C17*Y17,IF(AND(10<=$C17,$C17<=50),$C17*Z17,IF($C17>50,$C17*AA17,"No Offer"))),"No Offer"))
C18: ='Series 200 Input'!J18 -> 0
A19: 2/012 | B19: Take up or down and remove to tip off site precast concrete tactile paving slab paving 50mm thick | C19: ='Series 200 Input'!J19 -> 0 | D19: m2 | E19: 43.15 | F19: 10.68 | G19: 10.68 | H19: =IF((0=$C19),"",IFERROR(IF($C19<10,$C19*E19,IF(AND(10<=$C19,$C19<=50),$C19*F19,IF($C19>50,$C19*G19,"No Offer"))),"No Offer")) | I19: 3 | J19: 3 | K19: 3 | L19: =IF((0=$C19),"",IFERROR(IF($C19<10,$C19*I19,IF(AND(10<=$C19,$C19<=50),$C19*J19,IF($C19>50,$C19*K19,"No Offer"))),"No Offer")) | M19: 7.43 | N19: 7.43 | O19: 7.43 | P19: =IF((0=$C19),"",IFERROR(IF($C19<10,$C19*M19,IF(AND(10<=$C19,$C19<=50),$C19*N19,IF($C19>50,$C19*O19,"No Offer"))),"No Offer")) | Q19: 4 | R19: 4 | S19: 4 | T19: =IF((0=$C19),"",IFERROR(IF($C19<10,$C19*Q19,IF(AND(10<=$C19,$C19<=50),$C19*R19,IF($C19>50,$C19*S19,"No Offer"))),"No Offer")) | U19: 7.8 | V19: 6.37 | W19: 6 | X19: =IF((0=$C19),"",IFERROR(IF($C19<10,$C19*U19,IF(AND(10<=$C19,$C19<=50),$C19*V19,IF($C19>50,$C19*W19,"No Offer"))),"No Offer")) | Y19: No Offer | Z19: No Offer | AA19: No Offer | AB19: =IF((0=$C19),"",IFERROR(IF($C19<10,$C19*Y19,IF(AND(10<=$C19,$C19<=50),$C19*Z19,IF($C19>50,$C19*AA19,"No Offer"))),"No Offer"))
C20: ='Series 200 Input'!J20 -> 0
A21: 2/013 | B21: Take up or down and remove to tip off site precast concrete tactile paving slab paving 65mm thick | C21: ='Series 200 Input'!J21 -> 0 | D21: m2 | E21: 43.15 | F21: 11.87 | G21: 11.87 | H21: =IF((0=$C21),"",IFERROR(IF($C21<10,$C21*E21,IF(AND(10<=$C21,$C21<=50),$C21*F21,IF($C21>50,$C21*G21,"No Offer"))),"No Offer")) | I21: 3 | J21: 3 | K21: 3 | L21: =IF((0=$C21),"",IFERROR(IF($C21<10,$C21*I21,IF(AND(10<=$C21,$C21<=50),$C21*J21,IF($C21>50,$C21*K21,"No Offer"))),"No Offer")) | M21: 9.32 | N21: 9.32 | O21: 9.32 | P21: =IF((0=$C21),"",IFERROR(IF($C21<10,$C21*M21,IF(AND(10<=$C21,$C21<=50),$C21*N21,IF($C21>50,$C21*O21,"No Offer"))),"No Offer")) | Q21: 4 | R21: 4 | S21: 4 | T21: =IF((0=$C21),"",IFERROR(IF($C21<10,$C21*Q21,IF(AND(10<=$C21,$C21<=50),$C21*R21,IF($C21>50,$C21*S21,"No Offer"))),"No Offer")) | U21: 9 | V21: 7.8 | W21: 7.2 | X21: =IF((0=$C21),"",IFERROR(IF($C21<10,$C21*U21,IF(AND(10<=$C21,$C21<=50),$C21*V21,IF($C21>50,$C21*W21,"No Offer"))),"No Offer")) | Y21: No Offer | Z21: No Offer | AA21: No Offer | AB21: =IF((0=$C21),"",IFERROR(IF($C21<10,$C21*Y21,IF(AND(10<=$C21,$C21<=50),$C21*Z21,IF($C21>50,$C21*AA21,"No Offer"))),"No Offer"))
C22: ='Series 200 Input'!J22 -> 0
A23: 2/014 | B23: Take up or down and remove to tip off site precast concrete hazard paving slab paving 50mm thick | C23: ='Series 200 Input'!J23 -> 0 | D23: m2 | E23: 43.15 | F23: 10.68 | G23: 10.68 | H23: =IF((0=$C23),"",IFERROR(IF($C23<10,$C23*E23,IF(AND(10<=$C23,$C23<=50),$C23*F23,IF($C23>50,$C23*G23,"No Offer"))),"No Offer")) | I23: 3 | J23: 3 | K23: 3 | L23: =IF((0=$C23),"",IFERROR(IF($C23<10,$C23*I23,IF(AND(10<=$C23,$C23<=50),$C23*J23,IF($C23>50,$C23*K23,"No Offer"))),"No Offer")) | M23: 7.43 | N23: 7.43 | O23: 7.43 | P23: =IF((0=$C23),"",IFERROR(IF($C23<10,$C23*M23,IF(AND(10<=$C23,$C23<=50),$C23*N23,IF($C23>50,$C23*O23,"No Offer"))),"No Offer")) | Q23: 4 | R23: 4 | S23: 4 | T23: =IF((0=$C23),"",IFERROR(IF($C23<10,$C23*Q23,IF(AND(10<=$C23,$C23<=50),$C23*R23,IF($C23>50,$C23*S23,"No Offer"))),"No Offer")) | U23: 7.8 | V23: 6.37 | W23: 6 | X23: =IF((0=$C23),"",IFERROR(IF($C23<10,$C23*U23,IF(AND(10<=$C23,$C23<=50),$C23*V23,IF($C23>50,$C23*W23,"No Offer"))),"No Offer")) | Y23: No Offer | Z23: No Offer | AA23: No Offer | AB23: =IF((0=$C23),"",IFERROR(IF($C23<10,$C23*Y23,IF(AND(10<=$C23,$C23<=50),$C23*Z23,IF($C23>50,$C23*AA23,"No Offer"))),"No Offer"))
C24: ='Series 200 Input'!J24 -> 0
A25: 2/015 | B25: Take up or down and remove to tip off site precast concrete hazard paving slab paving 65mm thick | C25: ='Series 200 Input'!J25 -> 0 | D25: m2 | E25: 43.15 | F25: 11.87 | G25: 11.87 | H25: =IF((0=$C25),"",IFERROR(IF($C25<10,$C25*E25,IF(AND(10<=$C25,$C25<=50),$C25*F25,IF($C25>50,$C25*G25,"No Offer"))),"No Offer")) | I25: 3 | J25: 3 | K25: 3 | L25: =IF((0=$C25),"",IFERROR(IF($C25<10,$C25*I25,IF(AND(10<=$C25,$C25<=50),$C25*J25,IF($C25>50,$C25*K25,"No Offer"))),"No Offer")) | M25: 9.32 | N25: 9.32 | O25: 9.32 | P25: =IF((0=$C25),"",IFERROR(IF($C25<10,$C25*M25,IF(AND(10<=$C25,$C25<=50),$C25*N25,IF($C25>50,$C25*O25,"No Offer"))),"No Offer")) | Q25: 4 | R25: 4 | S25: 4 | T25: =IF((0=$C25),"",IFERROR(IF($C25<10,$C25*Q25,IF(AND(10<=$C25,$C25<=50),$C25*R25,IF($C25>50,$C25*S25,"No Offer"))),"No Offer")) | U25: 9 | V25: 7.8 | W25: 7.2 | X25: =IF((0=$C25),"",IFERROR(IF($C25<10,$C25*U25,IF(AND(10<=$C25,$C25<=50),$C25*V25,IF($C25>50,$C25*W25,"No Offer"))),"No Offer")) | Y25: No Offer | Z25: No Offer | AA25: No Offer | AB25: =IF((0=$C25),"",IFERROR(IF($C25<10,$C25*Y25,IF(AND(10<=$C25,$C25<=50),$C25*Z25,IF($C25>50,$C25*AA25,"No Offer"))),"No Offer"))
C26: ='Series 200 Input'!J26 -> 0
